Workbook

Sheet Board Dashboard
A1: Board Dashboard - AI Security and Governance Posture
A2: Board-level summary of AI governance, risk, compliance, service delivery and strategic posture. Owner: AI Security Manager. Reporting period: Q1 2026 (as at 02/05/2026).
A3: Navigation: Board Pack Notes | Operational Dashboard | Executive Report | TOM Index | ID Glossary
A5: 1. Headline Posture
A6: ISO 42001 Control Implementation | D6: Maturity vs Target | G6: Total Residual Exposure (GBP M) | J6: High/Critical Residual Risks
A7: =IFERROR('Compliance Mapping'!U16,"N/A") -> 0.75 | D7: =IFERROR(SUM('Maturity Assessment'!D4:D12)/SUM('Maturity Assessment'!F4:F12),"N/A") -> 0.76470588 | G7: =IFERROR(SUM('Risk Quantification'!L5:L17),"N/A") -> 53.7 | J7: =COUNTIF('Risk Quantification'!K5:K17,">="&15) -> 0
A8: Controls implemented / total (16 controls in scope) | D8: Composite of 9 domains vs target | G8: Sum of quantified residual exposure (13 risks) | J8: Risks with residual score >=15 (max 25)
A10: KRI Breaches (Red + Amber) | D10: Open High-Severity Incidents | G10: Overdue Roadmap Items | J10: Tier-1 Vendor DD Currency
A11: =COUNTIF('KRI Tracking'!J5:J13,"Red")+COUNTIF('KRI Tracking'!J5:J13,"Amber") -> 2 | D11: =COUNTIFS('Incident Analysis'!D5:D12,"Sev 1",'Incident Analysis'!M5:M12,"<>Closed")+COUNTIFS('Incident Analysis'!D5:D12,"Sev 2",'Incident Analysis'!M5:M12,"<>Closed") -> 0 | G11: =COUNTIF('Implementation Roadmap'!H5:H16,"Delayed") -> 0 | J11: =IFERROR(COUNTIFS('Third-Party Risk Services'!G5:G20,"Complete",'Third-Party Risk Services'!N5:N20,"High*")/COUNTIF('Third-Party Risk Services'!N5:N20,"High*"),"N/A") -> 1
A12: KRIs above amber or red threshold | D12: Sev 1/2 incidents open or under review (90d) | G12: Roadmap items with Delayed status | J12: High-criticality vendors with DD complete
A14: 2. Top 5 Material Risks (by Quantified Residual Exposure)
A15: Risk ID | C15: Risk Title | G15: Residual Score | H15: Exposure (GBP M) | I15: Treatment | J15: Treatment Action | K15: Owner
A16: ='Risk Quantification'!A15 -> RSK-011 | C16: ='Risk Quantification'!B15 -> Regulatory breach (Consumer Duty / fairness / FCA) | G16: ='Risk Quantification'!K15 -> 10 | H16: ='Risk Quantification'!L15 -> 7.5 | I16: ='Risk Quantification'!M15 -> Mitigate | J16: ='Risk Quantification'!N15 -> ACT-012 | K16: =IFERROR(INDEX('Implementation Roadmap'!E$5:E$16,MATCH('Risk Quantification'!N15,'Implementation Roadmap'!A$5:A$16,0)),"See Action") -> See Action
A17: ='Risk Quantification'!A5 -> RSK-001 | C17: ='Risk Quantification'!B5 -> Model performance drift causing pricing/UW losses | G17: ='Risk Quantification'!K5 -> 8 | H17: ='Risk Quantification'!L5 -> 6.5 | I17: ='Risk Quantification'!M5 -> Mitigate | J17: ='Risk Quantification'!N5 -> ACT-001 | K17: =IFERROR(INDEX('Implementation Roadmap'!E$5:E$16,MATCH('Risk Quantification'!N5,'Implementation Roadmap'!A$5:A$16,0)),"See Action") -> See Action
A18: ='Risk Quantification'!A14 -> RSK-010 | C18: ='Risk Quantification'!B14 -> Cloud misconfiguration exposing AI workloads | G18: ='Risk Quantification'!K14 -> 10 | H18: ='Risk Quantification'!L14 -> 6 | I18: ='Risk Quantification'!M14 -> Mitigate | J18: ='Risk Quantification'!N14 -> ACT-011 | K18: =IFERROR(INDEX('Implementation Roadmap'!E$5:E$16,MATCH('Risk Quantification'!N14,'Implementation Roadmap'!A$5:A$16,0)),"See Action") -> See Action
A19: ='Risk Quantification'!A8 -> RSK-004 | C19: ='Risk Quantification'!B8 -> Pricing/fairness bias against protected groups | G19: ='Risk Quantification'!K8 -> 8 | H19: ='Risk Quantification'!L8 -> 5.5 | I19: ='Risk Quantification'!M8 -> Mitigate | J19: ='Risk Quantification'!N8 -> ACT-006 | K19: =IFERROR(INDEX('Implementation Roadmap'!E$5:E$16,MATCH('Risk Quantification'!N8,'Implementation Roadmap'!A$5:A$16,0)),"See Action") -> See Action
A20: ='Risk Quantification'!A9 -> RSK-005 | C20: ='Risk Quantification'!B9 -> LLM hallucination delivered to customer | G20: ='Risk Quantification'!K9 -> 8 | H20: ='Risk Quantification'!L9 -> 4.8 | I20: ='Risk Quantification'!M9 -> Mitigate | J20: ='Risk Quantification'!N9 -> ACT-007 | K20: =IFERROR(INDEX('Implementation Roadmap'!E$5:E$16,MATCH('Risk Quantification'!N9,'Implementation Roadmap'!A$5:A$16,0)),"See Action") -> See Action
A22: 3. Maturity by Domain (Current vs Target)
A23: Domain ID | C23: Domain | G23: Current | H23: Level | I23: Target | J23: Gap | K23: Owner
A24: ='Maturity Assessment'!A4 -> Domain ID | C24: ='Maturity Assessment'!B4 -> Domain | G24: ='Maturity Assessment'!D4 -> Current Maturity (1-5) | H24: ='Maturity Assessment'!E4 -> Current Level | I24: ='Maturity Assessment'!F4 -> Target Maturity (1-5) | J24: ='Maturity Assessment'!H4 -> Gap | K24: ='Maturity Assessment'!K4 -> Owner
A25: ='Maturity Assessment'!A5 -> MAT-01 | C25: ='Maturity Assessment'!B5 -> Governance | G25: ='Maturity Assessment'!D5 -> 4 | H25: ='Maturity Assessment'!E5 -> Managed | I25: ='Maturity Assessment'!F5 -> 5 | J25: ='Maturity Assessment'!H5 -> 1 | K25: ='Maturity Assessment'!K5 -> Andrew Pollard
A26: ='Maturity Assessment'!A6 -> MAT-02 | C26: ='Maturity Assessment'!B6 -> Risk Management | G26: ='Maturity Assessment'!D6 -> 3 | H26: ='Maturity Assessment'!E6 -> Defined | I26: ='Maturity Assessment'!F6 -> 4 | J26: ='Maturity Assessment'!H6 -> 1 | K26: ='Maturity Assessment'!K6 -> Geoffrey Sanders
A27: ='Maturity Assessment'!A7 -> MAT-03 | C27: ='Maturity Assessment'!B7 -> Security Controls | G27: ='Maturity Assessment'!D7 -> 4 | H27: ='Maturity Assessment'!E7 -> Managed | I27: ='Maturity Assessment'!F7 -> 5 | J27: ='Maturity Assessment'!H7 -> 1 | K27: ='Maturity Assessment'!K7 -> Karen Holloway
A28: ='Maturity Assessment'!A8 -> MAT-04 | C28: ='Maturity Assessment'!B8 -> Privacy and Data Handling | G28: ='Maturity Assessment'!D8 -> 3 | H28: ='Maturity Assessment'!E8 -> Defined | I28: ='Maturity Assessment'!F8 -> 4 | J28: ='Maturity Assessment'!H8 -> 1 | K28: ='Maturity Assessment'!K8 -> Rebecca Lloyd
A29: ='Maturity Assessment'!A9 -> MAT-05 | C29: ='Maturity Assessment'!B9 -> Monitoring and Assurance | G29: ='Maturity Assessment'!D9 -> 3 | H29: ='Maturity Assessment'!E9 -> Defined | I29: ='Maturity Assessment'!F9 -> 4 | J29: ='Maturity Assessment'!H9 -> 1 | K29: ='Maturity Assessment'!K9 -> Mohammed Iqbal
A30: ='Maturity Assessment'!A10 -> MAT-06 | C30: ='Maturity Assessment'!B10 -> Third-Party Oversight | G30: ='Maturity Assessment'!D10 -> 3 | H30: ='Maturity Assessment'!E10 -> Defined | I30: ='Maturity Assessment'!F10 -> 4 | J30: ='Maturity Assessment'!H10 -> 1 | K30: ='Maturity Assessment'!K10 -> Sarah Mitchell
A31: ='Maturity Assessment'!A11 -> MAT-07 | C31: ='Maturity Assessment'!B11 -> Lifecycle Management | G31: ='Maturity Assessment'!D11 -> 3 | H31: ='Maturity Assessment'!E11 -> Defined | I31: ='Maturity Assessment'!F11 -> 4 | J31: ='Maturity Assessment'!H11 -> 1 | K31: ='Maturity Assessment'!K11 -> Daniel O'Reilly
A32: ='Maturity Assessment'!A12 -> MAT-08 | C32: ='Maturity Assessment'!B12 -> Resilience and Continuity | G32: ='Maturity Assessment'!D12 -> 3 | H32: ='Maturity Assessment'!E12 -> Defined | I32: ='Maturity Assessment'!F12 -> 4 | J32: ='Maturity Assessment'!H12 -> 1 | K32: ='Maturity Assessment'!K12 -> Yvonne Mathieson
A33: Average / Total | G33: =AVERAGE(G24:G32) -> 3.25 | I33: =AVERAGE(I24:I32) -> 4.25 | J33: =SUM(J24:J32) -> 8
A35: 4. Key Risk Indicators (KRI) Summary
A36: KRI ID | C36: KRI Name | F36: Current | G36: Amber | H36: Red | I36: Trend | J36: Status | K36: Owner
A37: ='KRI Tracking'!A5 -> KRI-001 | C37: ='KRI Tracking'!B5 -> Models with material drift in last 30 days | F37: ='KRI Tracking'!G5 -> 1 | G37: ='KRI Tracking'!E5 -> 2 | H37: ='KRI Tracking'!F5 -> 4 | I37: ='KRI Tracking'!I5 -> Improving | J37: ='KRI Tracking'!J5 -> Green | K37: ='KRI Tracking'!K5 -> Mohammed Iqbal
A38: ='KRI Tracking'!A6 -> KRI-002 | C38: ='KRI Tracking'!B6 -> Tier-1 models without current monitoring coverage | F38: ='KRI Tracking'!G6 -> 0 | G38: ='KRI Tracking'!E6 -> 1 | H38: ='KRI Tracking'!F6 -> 2 | I38: ='KRI Tracking'!I6 -> Stable | J38: ='KRI Tracking'!J6 -> Green | K38: ='KRI Tracking'!K6 -> Mohammed Iqbal
A39: ='KRI Tracking'!A7 -> KRI-003 | C39: ='KRI Tracking'!B7 -> Pricing fairness review breaches outstanding | F39: ='KRI Tracking'!G7 -> 0 | G39: ='KRI Tracking'!E7 -> 1 | H39: ='KRI Tracking'!F7 -> 3 | I39: ='KRI Tracking'!I7 -> Stable | J39: ='KRI Tracking'!J7 -> Green | K39: ='KRI Tracking'!K7 -> Helen Carter
A40: ='KRI Tracking'!A8 -> KRI-004 | C40: ='KRI Tracking'!B8 -> Customer-facing AI complaints linked to AI behaviour (rolling 90d) | F40: ='KRI Tracking'!G8 -> 3 | G40: ='KRI Tracking'!E8 -> 5 | H40: ='KRI Tracking'!F8 -> 10 | I40: ='KRI Tracking'!I8 -> Improving | J40: ='KRI Tracking'!J8 -> Green | K40: ='KRI Tracking'!K8 -> Olivia Bennett
A41: ='KRI Tracking'!A9 -> KRI-005 | C41: ='KRI Tracking'!B9 -> Vulnerable customer cases handled outside specialist team | F41: ='KRI Tracking'!G9 -> 1 | G41: ='KRI Tracking'!E9 -> 2 | H41: ='KRI Tracking'!F9 -> 5 | I41: ='KRI Tracking'!I9 -> Stable | J41: ='KRI Tracking'!J9 -> Green | K41: ='KRI Tracking'!K9 -> Olivia Bennett
A42: ='KRI Tracking'!A10 -> KRI-006 | C42: ='KRI Tracking'!B10 -> Sanctions/fraud false-negative incidents (rolling 90d) | F42: ='KRI Tracking'!G10 -> 0 | G42: ='KRI Tracking'!E10 -> 1 | H42: ='KRI Tracking'!F10 -> 2 | I42: ='KRI Tracking'!I10 -> Improving | J42: ='KRI Tracking'!J10 -> Green | K42: ='KRI Tracking'!K10 -> Helen Carter
A43: ='KRI Tracking'!A11 -> KRI-007 | C43: ='KRI Tracking'!B11 -> DLP exceptions raised on GenAI tools (per month) | F43: ='KRI Tracking'!G11 -> 14 | G43: ='KRI Tracking'!E11 -> 10 | H43: ='KRI Tracking'!F11 -> 20 | I43: ='KRI Tracking'!I11 -> Deteriorating | J43: ='KRI Tracking'!J11 -> Amber | K43: ='KRI Tracking'!K11 -> Karen Holloway
A44: ='KRI Tracking'!A12 -> KRI-008 | C44: ='KRI Tracking'!B12 -> Document AI extraction reject rate | F44: ='KRI Tracking'!G12 -> 3 | G44: ='KRI Tracking'!E12 -> 4 | H44: ='KRI Tracking'!F12 -> 8 | I44: ='KRI Tracking'!I12 -> Stable | J44: ='KRI Tracking'!J12 -> Green | K44: ='KRI Tracking'!K12 -> Mohammed Iqbal
A45: ='KRI Tracking'!A13 -> KRI-009 | C45: ='KRI Tracking'!B13 -> Cloud configuration drift on AI workloads | F45: ='KRI Tracking'!G13 -> 2 | G45: ='KRI Tracking'!E13 -> 2 | H45: ='KRI Tracking'!F13 -> 5 | I45: ='KRI Tracking'!I13 -> Stable | J45: ='KRI Tracking'!J13 -> Amber | K45: ='KRI Tracking'!K13 -> Karen Holloway
...

Sheet Board Pack Notes
A1: Board Pack Notes - Q1 2026
A2: Concise companion to the Board Dashboard. Threshold definitions, board metric interpretation notes, decisions required this quarter and narrative on major changes since last review. Owner AI Security Manager.
A3: Board Dashboard | B3: Operational Dashboard | C3: Executive Report | D3: ID Glossary | E3: ISO 42001 Matrix | F3: Evidence Register | G3: Mgmt Review | H3: TOM and Strategy
B5: 1. Board Metric Interpretation Notes
B6: Metric | C6: What it Tells the Board | D6: How it is Calculated | E6: Why it Matters | F6: Source Sheet | G6: Cadence | H6: Owner
B7: ISO 42001 Audit Readiness | C7: Average readiness across 38 ISO 42001 clauses and Annex A controls | D7: Average of readiness score 0-3 divided by 3 across 38 items | E7: Indicates how prepared the AIMS would be for an external 42001 assessment | F7: ISO 42001 Audit Readiness Matrix | G7: Quarterly | H7: Sarah Mitchell
B8: Maturity vs Target | C8: Composite maturity score expressed as percent of target | D8: Sum of current scores divided by sum of target scores across 9 domains | E8: Tracks progress toward target maturity 4.22 of 5 | F8: Maturity Assessment | G8: Half-yearly | H8: AI Security Manager
B9: Total Residual Exposure | C9: Sum of quantified residual exposure across all AI risks | D9: SUM of column L on Risk Quantification | E9: Headline financial exposure metric for risk appetite | F9: Risk Quantification | G9: Quarterly | H9: Geoffrey Sanders
B10: High Critical Residual Risks | C10: Number of risks with residual score 15 or higher | D10: COUNTIF residual score greater than or equal to 15 (out of max 25) | E10: Identifies risks above board appetite for residual harm | F10: Risk Quantification | G10: Monthly | H10: Geoffrey Sanders
B11: Major NC Risks Open | C11: Number of audit readiness items where absence is a potential major nonconformity | D11: COUNTIF on Potential NC column starts with Major | E11: Indicates audit-blocking gaps that need closure before assessment | F11: ISO 42001 Audit Readiness Matrix | G11: Quarterly | H11: Sarah Mitchell
B12: KRI Breaches Red and Amber | C12: Forward-looking risk indicators above amber threshold | D12: COUNTIF KRI status equals Red or Amber | E12: Early warning signal for emerging risk concentrations | F12: KRI Tracking | G12: Monthly | H12: AI Security Manager
B13: Open and High Severity Incidents | C13: Sev 1/2 incidents in rolling 90 days plus open or under-review incidents | D13: COUNTIF on severity Sev 1 plus Sev 2 plus Open | E13: Operational AI risk crystallisation indicator | F13: Incident Analysis | G13: Continuous | H13: AI Security Manager
B14: Overdue Corrective Actions | C14: Open corrective actions past target close date | D14: SUMPRODUCT on status not Closed and target date in past | E14: Indicates remediation discipline and audit-readiness risk | F14: Management Review and Internal Audit Tracker | G14: Monthly | H14: AI Security Manager
B15: Tier-1 Control Coverage | C15: Number of Tier-1 use cases with each material control linked | D15: SUMPRODUCT counting Tier-1 use cases linked to specific control IDs | E15: Indicates control depth on critical AI use cases | F15: AI Use Case Register | G15: Quarterly | H15: Mohammed Iqbal
B16: Evidence Currency Pct | C16: Percent of evidence items with current next-review date | D16: COUNTIF evidence currency Current divided by total | E16: Indicator of audit-readiness of evidence library | F16: Evidence Register | G16: Monthly | H16: Sarah Mitchell
B18: 2. Threshold and RAG Rule Definitions
B19: Indicator | C19: Green | D19: Amber | E19: Red | F19: Notes | G19: Source | H19: Owner
B20: ISO 42001 Audit Readiness pct | C20: 85 percent or higher | D20: 70 to 85 percent | E20: Below 70 percent | F20: Composite of 38 items each 0-3 score | G20: ISO 42001 Audit Readiness Matrix | H20: Sarah Mitchell
B21: Maturity vs Target pct | C21: 85 percent or higher | D21: 70 to 85 percent | E21: Below 70 percent | F21: Sum of current divided by sum of target across 9 domains | G21: Maturity Assessment | H21: AI Security Manager
B22: Major NC Risks Open | C22: Zero | D22: 1 to 5 | E22: More than 5 | F22: Items where absence is a major NC risk | G22: ISO 42001 Audit Readiness Matrix | H22: Sarah Mitchell
B23: High Critical Residual Risks | C23: Zero | D23: 1 | E23: More than 1 | F23: Residual score greater than or equal to 15 | G23: Risk Quantification | H23: Geoffrey Sanders
B24: KRI Breaches Red and Amber | C24: Zero | D24: 1 to 2 | E24: More than 2 | F24: KRI breach status either Red or Amber | G24: KRI Tracking | H24: AI Security Manager
B25: Open Incidents | C25: Zero | D25: 1 to 2 | E25: More than 2 | F25: Open or Under Review status | G25: Incident Analysis | H25: AI Security Manager
B26: Overdue Corrective Actions | C26: Zero | D26: 1 to 2 | E26: More than 2 | F26: Open or In Progress with target date in past | G26: Management Review and Internal Audit Tracker | H26: AI Security Manager
B27: Maturity Score 1-5 | C27: 4 or 5 (Managed or Optimised) | D27: 3 (Defined) | E27: 1 or 2 (Initial or Developing) | F27: Per-domain maturity rating | G27: Maturity Assessment | H27: AI Security Manager
B28: Vendor Residual | C28: Green - all assurance current | D28: Amber - one or more assurance items pending | E28: Red - material assurance gap | F28: Per-vendor residual posture | G28: Third-Party Risk Services | H28: Sarah Mitchell
B29: Days to Target on Corrective Actions | C29: Greater than 30 days | D29: 0 to 30 days | E29: Negative (overdue) | F29: Days to target close date | G29: Management Review and Internal Audit Tracker | H29: AI Security Manager
B31: 3. Decisions Required This Quarter
B32: Decision ID | C32: Decision | D32: Recommendation | E32: Forum | F32: Owner | G32: Decision By | H32: Linked Item
B33: DEC-Q1-01 | C33: Approve closure plan for 4 major-NC-risk areas (CA-009, CA-010, CA-011, CA-014) | D33: Approve and resource the closure plan ahead of internal readiness review | E33: AI Governance Forum | F33: Sarah Mitchell | G33: 30/06/2026 | H33: Mgmt Review tracker Section 3
B34: DEC-Q1-02 | C34: Approve Tier-1 vendor exit plans (VEN-001 Microsoft, VEN-006 Sentinel) | D34: Approve documented substitutability assessments and exit plans | E34: Third-Party Oversight Forum | F34: Sarah Mitchell | G34: 30/09/2026 | H34: Third-Party Risk Services
B35: DEC-Q1-03 | C35: Approve net hire of 5 FTE to close resource gap | D35: Approve hiring in line with FY26/27 plan | E35: ExCo | F35: Sarah Mitchell | G35: 30/06/2026 | H35: Resource Planning
B36: DEC-Q1-04 | C36: Reset risk appetite for residual AI risk pending refreshed quantification (RDM-012) | D36: Reaffirm appetite; commit to scenario-range refresh | E36: Risk Committee Board | F36: Geoffrey Sanders | G36: 30/09/2026 | H36: Risk Quantification
B37: DEC-Q1-05 | C37: Approve ISO 42001 readiness review pack and certification path | D37: Approve subject to AUDIT-006 outcome | E37: ExCo / Risk Committee | F37: Sarah Mitchell | G37: 31/01/2027 | H37: ISO 42001 Audit Readiness Matrix
B38: DEC-Q1-06 | C38: Approve Salesforce Einstein-feature posture | D38: Maintain restricted posture pending vendor AI feature review | E38: AI Governance Forum | F38: Olivia Bennett | G38: 30/06/2026 | H38: AI Use Case Register AUC-004
B40: 4. Narrative on Major Changes Since Last Review (Q4 2025 to Q1 2026)
B41: Theme | C41: What Changed | D41: So What for the Board | E41: Linked IDs | F41: Owner
B42: ISO 42001 Readiness | C42: Internal readiness programme RDM-007 lifted to 50 percent complete; AIMS scope statement and AI policy approved; first internal audit AUDIT-001 closed | D42: Credible glide-path to internal readiness review Q4 2026 and certification readiness assessment Q1 2027 | E42: RDM-007; AUDIT-001; EVD-023; EVD-024 | F42: Sarah Mitchell
B43: Customer-Facing AI | C43: Hallucination filter retuned post INC-008; PIR-008 closed; sample QA increased; vendor change-window controls being aligned with QA windows | D43: Operational risk on customer-facing GenAI demonstrably reduced; CTL-007 and CTL-010 strengthened | E43: INC-008; CA-008; CTL-007; CTL-010 | F43: Olivia Bennett
B44: Third-Party Posture | C44: Tier-1 vendor due diligence currency at 94 percent against 100 target; two Tier-1 exit plans documented with remainder in flight; ABBYY privacy review in progress | D44: Concentration risk on Microsoft platform remains the largest substitutability concern; CA-011 closure expected Sep 2026 | E44: VEN-001; VEN-006; CA-008; CA-011 | F44: Sarah Mitchell
...

Sheet Board KPI-KRI Tracker
A1: Board KPI-KRI Tracker - Leading Indicators for AI Security and Governance
A2: Forward-looking (leading) indicators that predict emerging risk before it materialises. These complement lagging indicators (incidents, losses) by providing early warning for board-level oversight. Owner: AI Security Manager. As at 02/05/2026.
A3: Navigation: Board Dashboard | KRI Tracking | KPI Tracking | Risk Quantification | Maturity Assessment | Board Pack Notes
A5: LEADING vs LAGGING: Leading indicators measure conditions that precede risk events (e.g., control coverage gaps, training shortfalls, overdue reviews, configuration drift). They enable proactive intervention BEFORE harm occurs. Lagging indicators (e.g., incident count, customer complaints, financial losses) confirm risk has already crystallised. This tracker focuses on LEADING indicators to give the Board predictive visibility into the AI risk posture.
A8: Section 1: Leading Key Risk Indicators (KRIs) - Early Warning Signals
A9: ID | B9: Leading Indicator | C9: Linked Risk | D9: Current | E9: Amber | F9: Red | G9: Target | H9: Status | I9: Trend | J9: Predictive Signal | K9: Lead Time | L9: Owner | M9: Escalation | N9: Board Action if Breached
A10: ='KRI Tracking'!A5 -> KRI-001 | B10: ='KRI Tracking'!B5 -> Models with material drift in last 30 days | C10: ='KRI Tracking'!C5 -> RSK-001 | D10: ='KRI Tracking'!G5 -> 1 | E10: ='KRI Tracking'!E5 -> 2 | F10: ='KRI Tracking'!F5 -> 4 | G10: ='KRI Tracking'!H5 -> 0 | H10: ='KRI Tracking'!J5 -> Green | I10: ='KRI Tracking'!I5 -> Improving | J10: Drift precedes model failure; early signal of pricing/claims errors before customer impact | K10: 2-4 weeks before incident | L10: ='KRI Tracking'!K5 -> Mohammed Iqbal | M10: ='KRI Tracking'!N5 -> BAU | N10: Escalate to Model Risk Committee; invoke champion-challenger fallback
A11: ='KRI Tracking'!A6 -> KRI-002 | B11: ='KRI Tracking'!B6 -> Tier-1 models without current monitoring coverage | C11: ='KRI Tracking'!C6 -> RSK-002 | D11: ='KRI Tracking'!G6 -> 0 | E11: ='KRI Tracking'!E6 -> 1 | F11: ='KRI Tracking'!F6 -> 2 | G11: ='KRI Tracking'!H6 -> 0 | H11: ='KRI Tracking'!J6 -> Green | I11: ='KRI Tracking'!I6 -> Stable | J11: Unmonitored models cannot detect degradation; gap precedes undetected failure | K11: 4-8 weeks before undetected drift | L11: ='KRI Tracking'!K6 -> Mohammed Iqbal | M11: ='KRI Tracking'!N6 -> BAU | N11: Mandate monitoring reinstatement within 5 working days
A12: ='KRI Tracking'!A7 -> KRI-003 | B12: ='KRI Tracking'!B7 -> Pricing fairness review breaches outstanding | C12: ='KRI Tracking'!C7 -> RSK-001 | D12: ='KRI Tracking'!G7 -> 0 | E12: ='KRI Tracking'!E7 -> 1 | F12: ='KRI Tracking'!F7 -> 3 | G12: ='KRI Tracking'!H7 -> 0 | H12: ='KRI Tracking'!J7 -> Green | I12: ='KRI Tracking'!I7 -> Stable | J12: Outstanding fairness breaches signal future regulatory/Consumer Duty exposure | K12: 3-6 months before regulatory action | L12: ='KRI Tracking'!K7 -> Helen Carter | M12: ='KRI Tracking'!N7 -> BAU | N12: Suspend affected models; inform compliance and FCA engagement team
A13: ='KRI Tracking'!A8 -> KRI-004 | B13: ='KRI Tracking'!B8 -> Customer-facing AI complaints linked to AI behaviour (rolling 90d) | C13: ='KRI Tracking'!C8 -> RSK-005 | D13: ='KRI Tracking'!G8 -> 3 | E13: ='KRI Tracking'!E8 -> 5 | F13: ='KRI Tracking'!F8 -> 10 | G13: ='KRI Tracking'!H8 -> <=2 | H13: ='KRI Tracking'!J8 -> Green | I13: ='KRI Tracking'!I8 -> Improving | J13: Rising complaints trend predicts regulatory scrutiny and reputational damage | K13: 1-3 months before regulatory enquiry | L13: ='KRI Tracking'!K8 -> Olivia Bennett | M13: ='KRI Tracking'!N8 -> BAU | N13: Trigger Consumer Duty review; brief Risk Committee
A14: ='KRI Tracking'!A9 -> KRI-005 | B14: ='KRI Tracking'!B9 -> Vulnerable customer cases handled outside specialist team | C14: ='KRI Tracking'!C9 -> RSK-012 | D14: ='KRI Tracking'!G9 -> 1 | E14: ='KRI Tracking'!E9 -> 2 | F14: ='KRI Tracking'!F9 -> 5 | G14: ='KRI Tracking'!H9 -> 0 | H14: ='KRI Tracking'!J9 -> Green | I14: ='KRI Tracking'!I9 -> Stable | J14: Routing failures signal control weakness; predicts harm to vulnerable customers | K14: Immediate - each case is a near-miss | L14: ='KRI Tracking'!K9 -> Olivia Bennett | M14: ='KRI Tracking'!N9 -> BAU | N14: Invoke immediate remediation; report to Consumer Duty forum
A15: ='KRI Tracking'!A10 -> KRI-006 | B15: ='KRI Tracking'!B10 -> Sanctions/fraud false-negative incidents (rolling 90d) | C15: ='KRI Tracking'!C10 -> RSK-003 | D15: ='KRI Tracking'!G10 -> 0 | E15: ='KRI Tracking'!E10 -> 1 | F15: ='KRI Tracking'!F10 -> 2 | G15: ='KRI Tracking'!H10 -> 0 | H15: ='KRI Tracking'!J10 -> Green | I15: ='KRI Tracking'!I10 -> Improving | J15: Any false-negative signals model degradation; predicts undetected financial crime | K15: 1-2 weeks before leakage crystallises | L15: ='KRI Tracking'!K10 -> Helen Carter | M15: ='KRI Tracking'!N10 -> BAU | N15: Invoke SIU review; brief Fraud Committee and consider model suspension
A16: ='KRI Tracking'!A11 -> KRI-007 | B16: ='KRI Tracking'!B11 -> DLP exceptions raised on GenAI tools (per month) | C16: ='KRI Tracking'!C11 -> RSK-008 | D16: ='KRI Tracking'!G11 -> 14 | E16: ='KRI Tracking'!E11 -> 10 | F16: ='KRI Tracking'!F11 -> 20 | G16: ='KRI Tracking'!H11 -> <=8 | H16: ='KRI Tracking'!J11 -> Amber | I16: ='KRI Tracking'!I11 -> Deteriorating | J16: Rising DLP exceptions predict eventual data leakage before exfiltration occurs | K16: 2-6 weeks before potential breach | L16: ='KRI Tracking'!K11 -> Karen Holloway | M16: ='KRI Tracking'!N11 -> Monitor at next AIGF | N16: Restrict GenAI access for repeat offenders; brief CISO
A17: ='KRI Tracking'!A12 -> KRI-008 | B17: ='KRI Tracking'!B12 -> Document AI extraction reject rate | C17: ='KRI Tracking'!C12 -> RSK-006 | D17: ='KRI Tracking'!G12 -> 3 | E17: ='KRI Tracking'!E12 -> 4 | F17: ='KRI Tracking'!F12 -> 8 | G17: ='KRI Tracking'!H12 -> <=3 | H17: ='KRI Tracking'!J12 -> Green | I17: ='KRI Tracking'!I12 -> Stable | J17: Rising reject rates predict downstream claim errors before customer impact | K17: 1-2 weeks before payment errors | L17: ='KRI Tracking'!K12 -> Mohammed Iqbal | M17: ='KRI Tracking'!N12 -> BAU | N17: Invoke vendor escalation; increase manual QA sampling
A18: ='KRI Tracking'!A13 -> KRI-009 | B18: ='KRI Tracking'!B13 -> Cloud configuration drift on AI workloads | C18: ='KRI Tracking'!C13 -> RSK-010 | D18: ='KRI Tracking'!G13 -> 2 | E18: ='KRI Tracking'!E13 -> 2 | F18: ='KRI Tracking'!F13 -> 5 | G18: ='KRI Tracking'!H13 -> 0 | H18: ='KRI Tracking'!J13 -> Amber | I18: ='KRI Tracking'!I13 -> Stable | J18: Configuration drift signals exposure window; predicts cloud compromise before attack | K18: Days to weeks before exploitation | L18: ='KRI Tracking'!K13 -> Karen Holloway | M18: ='KRI Tracking'!N13 -> Monitor at next AIGF | N18: Emergency patching window; brief Technology Risk Committee
A20: Section 2: Leading Key Performance Indicators (KPIs) - Predictive Effectiveness Measures
A21: ID | B21: Leading Indicator | C21: Linked Service | D21: Target | E21: Actual | F21: Gap | G21: Status | H21: Trend | I21: Predictive Signal | J21: Lead Time | K21: Why Leading | L21: Owner | M21: Cadence | N21: Board Action if Off Track
A22: ='KPI Tracking'!A5 -> KPI-001 | B22: ='KPI Tracking'!B5 -> AI use case intake decisions on time (within 10 working days) | C22: ='KPI Tracking'!C5 -> SVC-001 | D22: ='KPI Tracking'!D5 -> 0.95 | E22: ='KPI Tracking'!E5 -> 0.97 | F22: =IFERROR(D22-E22,"") -> -0.02 | G22: ='KPI Tracking'!G5 -> On Track | H22: ='KPI Tracking'!F5 -> Improving | I22: Process speed predicts bottlenecks; delays signal governance overload before use cases stall | J22: 2-4 weeks before pipeline blockage | K22: Measures control process efficiency BEFORE it delays business value | L22: ='KPI Tracking'!H5 -> Daniel O'Reilly | M22: ='KPI Tracking'!I5 -> Monthly | N22: Review intake capacity; approve additional resource
A23: ='KPI Tracking'!A6 -> KPI-002 | B23: ='KPI Tracking'!B6 -> Material models with current independent assurance | C23: ='KPI Tracking'!C6 -> SVC-002 | D23: ='KPI Tracking'!D6 -> 0.98 | E23: ='KPI Tracking'!E6 -> 0.96 | F23: =IFERROR(D23-E23,"") -> 0.02 | G23: ='KPI Tracking'!G6 -> At Risk | H23: ='KPI Tracking'!F6 -> Stable | I23: Assurance gaps predict undetected model failure; declining coverage precedes incidents | J23: 4-8 weeks before undetected drift leads to loss | K23: Measures control coverage BEFORE failure occurs; gap = blind spot | L23: ='KPI Tracking'!H6 -> Mohammed Iqbal | M23: ='KPI Tracking'!I6 -> Monthly | N23: Mandate immediate re-validation; restrict model use until assured
A24: ='KPI Tracking'!A7 -> KPI-003 | B24: ='KPI Tracking'!B7 -> Claims AI uptime (monthly) | C24: ='KPI Tracking'!C7 -> SVC-003,SVC-010 | D24: ='KPI Tracking'!D7 -> 0.995 | E24: ='KPI Tracking'!E7 -> 0.997 | F24: =IFERROR(D24-E24,"") -> -0.002 | G24: ='KPI Tracking'!G7 -> On Track | H24: ='KPI Tracking'!F7 -> Stable | I24: Uptime trend predicts service reliability; degradation signals infrastructure stress before outage | J24: 1-2 weeks before prolonged outage | K24: Early degradation patterns (short dips) precede major failures | L24: ='KPI Tracking'!H7 -> Mohammed Iqbal | M24: ='KPI Tracking'!I7 -> Weekly | N24: Invoke resilience review; approve redundancy investment
A25: ='KPI Tracking'!A8 -> KPI-004 | B25: ='KPI Tracking'!B8 -> Fraud and sanctions FPR within agreed band | C25: ='KPI Tracking'!C8 -> SVC-004,SVC-012 | D25: ='KPI Tracking'!D8 -> 0.9 | E25: ='KPI Tracking'!E8 -> 0.92 | F25: =IFERROR(D25-E25,"") -> -0.02 | G25: ='KPI Tracking'!G8 -> On Track | H25: ='KPI Tracking'!F8 -> Improving | I25: Narrowing FPR band signals model calibration drift before fraud leakage occurs | J25: 2-4 weeks before false-negatives increase | K25: Threshold drift is visible before fraud leakage crystallises | L25: ='KPI Tracking'!H8 -> Helen Carter | M25: ='KPI Tracking'!I8 -> Monthly | N25: Invoke model recalibration; brief Fraud Committee
A26: ='KPI Tracking'!A9 -> KPI-005 | B26: ='KPI Tracking'!B9 -> Customer-facing AI sample QA pass rate | C26: ='KPI Tracking'!C9 -> SVC-005,SVC-009 | D26: ='KPI Tracking'!D9 -> 0.95 | E26: ='KPI Tracking'!E9 -> 0.93 | F26: =IFERROR(D26-E26,"") -> 0.02 | G26: ='KPI Tracking'!G9 -> At Risk | H26: ='KPI Tracking'!F9 -> Stable | I26: Declining QA pass rate predicts customer harm before complaints materialise | J26: 4-8 weeks before complaints spike | K26: Quality failures occur before customers notice and complain | L26: ='KPI Tracking'!H9 -> Olivia Bennett | M26: ='KPI Tracking'!I9 -> Monthly | N26: Restrict affected AI feature; invoke output filter review
A27: ='KPI Tracking'!A10 -> KPI-006 | B27: ='KPI Tracking'!B10 -> SOC mean-time-to-triage on AI-related alerts | C27: ='KPI Tracking'!C10 -> SVC-014 | D27: ='KPI Tracking'!D10 -> 15 | E27: ='KPI Tracking'!E10 -> 12 | F27: =IFERROR(D27-E27,"") -> 3 | G27: ='KPI Tracking'!G10 -> On Track | H27: ='KPI Tracking'!F10 -> Improving | I27: Rising triage time predicts SOC overload before alerts are missed | J27: 1-3 weeks before missed critical alert | K27: Response time degradation precedes missed detections | L27: ='KPI Tracking'!H10 -> Karen Holloway | M27: ='KPI Tracking'!I10 -> Weekly | N27: Approve SOC staffing increase; review alert prioritisation rules
A28: ='KPI Tracking'!A11 -> KPI-007 | B28: ='KPI Tracking'!B11 -> Tier-1 vendor due diligence currency | C28: ='KPI Tracking'!C11 -> SVC-015 | D28: ='KPI Tracking'!D11 -> 1 | E28: ='KPI Tracking'!E11 -> 0.94 | F28: =IFERROR(D28-E28,"") -> 0.06 | G28: ='KPI Tracking'!G11 -> Off Track | H28: ='KPI Tracking'!F11 -> Stable | I28: DD expiry signals assurance gap before vendor risk materialises | J28: 2-3 months before unassured vendor risk event | K28: Expired DD means blind spots on vendor changes that could harm us | L28: ='KPI Tracking'!H11 -> Sarah Mitchell | M28: ='KPI Tracking'!I11 -> Monthly | N28: Suspend new workloads to vendor; escalate renewal
A29: ='KPI Tracking'!A12 -> KPI-008 | B29: ='KPI Tracking'!B12 -> Document AI extraction QA reject rate | C29: ='KPI Tracking'!C12 -> SVC-006,SVC-011 | D29: ='KPI Tracking'!D12 -> 0.04 | E29: ='KPI Tracking'!E12 -> 0.03 | F29: =IFERROR(D29-E29,"") -> 0.01 | G29: ='KPI Tracking'!G12 -> On Track | H29: ='KPI Tracking'!F12 -> Stable | I29: Rising reject rate signals extraction model degradation before claim errors | J29: 1-2 weeks before incorrect payments | K29: Extraction failures precede downstream financial errors | L29: ='KPI Tracking'!H12 -> Mohammed Iqbal | M29: ='KPI Tracking'!I12 -> Monthly | N29: Invoke vendor review; increase manual sampling rate
A30: ='KPI Tracking'!A13 -> KPI-009 | B30: ='KPI Tracking'!B13 -> Claims triage SLA attainment | C30: ='KPI Tracking'!C13 -> SVC-003 | D30: ='KPI Tracking'!D13 -> 0.98 | E30: ='KPI Tracking'!E13 -> 0.985 | F30: =IFERROR(D30-E30,"") -> -0.005 | G30: ='KPI Tracking'!G13 -> On Track | H30: ='KPI Tracking'!F13 -> Improving | I30: SLA degradation predicts claims handling failures before customer detriment | J30: 1-2 weeks before customer harm | K30: Triage delays cause downstream SLA cascades | L30: ='KPI Tracking'!H13 -> James Whitfield | M30: ='KPI Tracking'!I13 -> Weekly | N30: Review capacity plan; invoke claims ops escalation
A31: ='KPI Tracking'!A14 -> KPI-010 | B31: ='KPI Tracking'!B14 -> Customer complaints linked to AI behaviour (per 1000 customers) | C31: ='KPI Tracking'!C14 -> SVC-005,SVC-009 | D31: ='KPI Tracking'!D14 -> 0.5 | E31: ='KPI Tracking'!E14 -> 0.4 | F31: =IFERROR(D31-E31,"") -> 0.1 | G31: ='KPI Tracking'!G14 -> On Track | H31: ='KPI Tracking'!F14 -> Improving | I31: Complaint trend predicts regulatory attention before FCA engagement | J31: 2-6 months before regulatory enquiry | K31: Rising trend visible months before regulator acts | L31: ='KPI Tracking'!H14 -> Olivia Bennett | M31: ='KPI Tracking'!I14 -> Monthly | N31: Brief Consumer Duty forum; prepare FCA response pack
A32: ='KPI Tracking'!A15 -> KPI-011 | B32: ='KPI Tracking'!B15 -> Internal GenAI tooling adoption (% of eligible users active monthly) | C32: ='KPI Tracking'!C15 -> SVC-007,SVC-008,SVC-009 | D32: ='KPI Tracking'!D15 -> 0.7 | E32: ='KPI Tracking'!E15 -> 0.73 | F32: =IFERROR(D32-E32,"") -> -0.03 | G32: ='KPI Tracking'!G15 -> On Track | H32: ='KPI Tracking'!F15 -> Stable | I32: Adoption plateau signals shadow AI risk; low adoption predicts ungoverned tool use | J32: 1-3 months before shadow AI incidents | K32: Low adoption drives users to ungoverned alternatives | L32: ='KPI Tracking'!H15 -> Karen Holloway | M32: ='KPI Tracking'!I15 -> Monthly | N32: Review UX barriers; extend training; communicate policy
A34: Section 3: Leading Indicator Summary - Board Attention Required
A35: KRI Breaches (Amber + Red) | C35: KRIs Deteriorating | E35: KPIs At Risk or Off Track | G35: Total Leading Indicators | I35: Overall Predictive Posture
A36: =COUNTIF(H10:H18,"Amber")+COUNTIF(H10:H18,"Red") -> 2 | C36: =COUNTIF(I10:I18,"Deteriorating") -> 1 | E36: =COUNTIF(G22:G32,"At Risk")+COUNTIF(G22:G32,"Off Track") -> 3 | G36: =COUNTA(A10:A18)+COUNTA(A22:A32) -> 20 | I36: =IF(COUNTIF(H10:H18,"Red")>0,"RED - Immediate Action Required",IF(A36+E36>4,"AMBER - Heightened Monitoring",IF(A36+E36>2,"AMBER - Monitor Closely","GREEN - Within Appetite"))) -> AMBER - Heightened Monitoring
A37: Early warning breaches | C37: Worsening trend direction | E37: Effectiveness gaps | G37: KRIs (9) + KPIs (11) | I37: Composite board-level assessment
A39: Section 4: Board Attention Items - Leading Indicators Signalling Emerging Risk
A40: Priority | B40: Indicator | C40: Current State | D40: Predictive Concern | H40: Board Action | L40: Timeline | M40: Owner | N40: Risk
A41: 1 | B41: DLP exceptions (KRI-007) | C41: 14/mth vs Amber 10; Deteriorating | D41: Predicts data leakage within 2-6 weeks. 3 BUs driving 80%. Pre-breach pattern. | H41: Restrict repeat-offender BU access; mandate training by 30/06/2026 | L41: Immediate | M41: K Holloway | N41: RSK-008
A42: 2 | B42: Cloud config drift (KRI-009) | C42: 2 findings vs Amber 2; Stable | D42: Exposed API endpoints. Exploitation lead time is days once threat actor discovers. | H42: Mandate 48-hour emergency remediation; approve out-of-cycle patch | L42: 48 hours | M42: K Holloway | N42: RSK-010
A43: 3 | B43: Vendor DD currency (KPI-007) | C43: 94% vs 100%; Off Track | D43: Tier-1 vendor in renewal with expired DD. Unassured platform changes introduce blind risk. | H43: Expedite renewal; restrict new workloads until DD refreshed | L43: 30 days | M43: S Mitchell | N43: RSK-008
A44: 4 | B44: QA pass rate (KPI-005) | C44: 93% vs 95%; At Risk | D44: Declining QA predicts complaints spike in 4-8 weeks. Filter retune needed post INC-008. | H44: Approve filter retune; increase QA sample to 10% | L44: 4 weeks | M44: O Bennett | N44: RSK-005
A45: 5 | B45: Training completion gap | C45: 86% vs 95% target | D45: Low completion correlates with DLP exceptions. Untrained staff 3x more likely to trigger. | H45: Mandate completion; withhold GenAI access for non-completers | L45: 30/06/2026 | M45: D O'Reilly | N45: RSK-008
A47: Section 5: RAG Threshold Definitions and Escalation Framework
...

Sheet Management Review and Internal 
A1: Management Review and Internal Audit Tracker - AIMS Effectiveness Evidence
A2: Tracks AIMS internal audits (Clause 9.2), management reviews (Clause 9.3), corrective actions and effectiveness reviews (Clause 10.1, 10.2) and continual improvement. Owner: AI Security Manager and Internal Audit. Cadence: Quarterly review.
A3: Back to Dashboard | Open ID Glossary | Board Dashboard | Executive Report | Compliance Mapping
A5: Section 1: Internal Audit Programme (ISO 42001 Clause 9.2)
A6: Audit ID | B6: Audit Title / Scope | C6: Clause | D6: Lead Auditor | E6: Status | F6: Date | G6: Findings | H6: Major NCs | I6: Minor NCs | J6: Observations | K6: Key Finding Summary | L6: Linked CA
A7: AUDIT-001 | B7: AIMS Governance and Policy Framework | C7: 4.1-5.3, 6.1 | D7: Liam Carmichael (CAE) | E7: Closed | F7: 15/01/2026 | G7: 4 | H7: 1 | I7: 2 | J7: 1 | K7: AIMS scope and policy approved; management review input checklist incomplete (Major NC); two minor gaps in documented roles. | L7: CA-009
A8: AUDIT-002 | B8: Customer-Facing AI Assurance | C8: 6.1.4, 8.1, 9.1 | D8: Liam Carmichael (CAE) | E8: Closed | F8: 28/02/2026 | G8: 3 | H8: 1 | I8: 1 | J8: 1 | K8: Impact assessments require refresh for customer-facing use cases after vendor sub-processor changes (Major NC). QA sampling adequate. | L8: CA-010
A9: AUDIT-003 | B9: Third-Party AI Oversight | C9: 8.1, A.7.5 | D9: Liam Carmichael (CAE) | E9: Closed | F9: 20/03/2026 | G9: 3 | H9: 1 | I9: 1 | J9: 1 | K9: Tier-1 vendor exit plans incomplete for VEN-001 and VEN-006 (Major NC). DD currency at 94% vs 100% target. | L9: CA-011
A10: AUDIT-004 | B10: Cloud and IAM Security Controls | C10: 8.1, A.6.2.4 | D10: External (KPMG) | E10: Closed | F10: 46299 | G10: 2 | H10: 0 | I10: 1 | J10: 1 | K10: Cloud CSPM controls effective; one minor finding on PAM bundle configuration (remediated). IAM controls satisfactory. | L10: CA-007
A11: AUDIT-005 | B11: AI Model Lifecycle and MRM | C11: 9.1, 9.2, A.6.2.6 | D11: Liam Carmichael (CAE) | E11: In Progress | F11: 30/06/2026 | K11: Scope: independent challenge of material models, validation backlog, model retirement process.
A12: AUDIT-006 | B12: ISO 42001 Internal Readiness Review | C12: All clauses + Annex A | D12: External (KPMG) | E12: Planned | F12: 30/09/2026 | K12: Full internal readiness assessment against 38 ISO 42001 clauses/Annex A items ahead of certification.
A14: Section 2: Management Reviews of the AIMS (ISO 42001 Clause 9.3)
A15: Review ID | B15: Review Title | C15: Date | D15: Chair | E15: Status | F15: Inputs Covered | G15: Key Decisions | H15: Actions Raised | I15: Effectiveness Confirmed | J15: Minutes Ref | K15: Next Review | L15: Linked Evidence
A16: MR-2025-Q3 | B16: AIMS Quarterly Management Review Q3 2025 | C16: 15/10/2025 | D16: Andrew Pollard (CDO) | E16: Closed | F16: Risk status, KPI/KRI, incidents, audit findings, resource, opportunities | G16: Approved AIMS scope; approved AI policy v1; noted resource gap | H16: 3 (CA-001, CA-002, CA-003) | I16: Yes - reviewed at MR-2025-Q4 | J16: EVD-027-MR-Q3 | K16: 15/01/2026 | L16: EVD-027
A17: MR-2025-Q4 | B17: AIMS Quarterly Management Review Q4 2025 | C17: 15/01/2026 | D17: Andrew Pollard (CDO) | E17: Closed | F17: Risk status, KPI/KRI, incidents, corrective actions, roadmap, vendor posture | G17: Approved ISO 42001 readiness programme; approved hiring plan; confirmed CA-001 effective | H17: 4 (CA-004, CA-005, CA-006, CA-007) | I17: Yes - reviewed at MR-2026-Q1 | J17: EVD-027-MR-Q4 | K17: 15/04/2026 | L17: EVD-027
A18: MR-2026-Q1 | B18: AIMS Quarterly Management Review Q1 2026 | C18: 15/04/2026 | D18: Andrew Pollard (CDO) | E18: Closed | F18: All 9.3 inputs: changes, performance, audits, NCs, KPIs, risks, opportunities, resources, continual improvement | G18: Approved closure plan for major NCs; noted vendor exit plan progress; approved training campaign escalation | H18: 5 (CA-009, CA-010, CA-011, CA-012, CA-014) | I18: Partial - PIR effectiveness pending | J18: EVD-027-MR-Q1-26 | K18: 15/07/2026 | L18: EVD-027
A19: MR-2026-Q2 | B19: AIMS Quarterly Management Review Q2 2026 | C19: 15/07/2026 | D19: Andrew Pollard (CDO) | E19: Scheduled | F19: All 9.3 inputs; effectiveness review of all closed PIRs; CA-009 to CA-014 progress review | K19: 15/10/2026 | L19: EVD-027
A21: Section 3: Corrective Actions Register (ISO 42001 Clause 10.1, 10.2)
A22: CA ID | B22: Corrective Action | C22: Source | D22: Root Cause | E22: Owner | F22: Target Date | G22: Status | H22: Days to Target | I22: Effectiveness Review | J22: Linked Audit/Incident | K22: Linked Control | L22: Priority
A23: CA-001 | B23: Add seasonality features to FNOL training set; tighten drift thresholds | C23: INC-001 / PIR-001 | D23: Seasonal claim composition not in training data | E23: Mohammed Iqbal | F23: 30/06/2026 | G23: Closed | H23: =IF(G23="Closed","",IFERROR(DATEVALUE(F23)-TODAY(),"")) | I23: Confirmed effective at MR-2025-Q4 | J23: AUDIT-001, INC-001 | K23: CTL-005 | L23: Medium
A24: CA-002 | B24: Complete ABBYY privacy review after sub-processor change | C24: AUDIT-003 / Vendor review | D24: Vendor sub-processor change triggered review | E24: Sarah Mitchell | F24: 30/06/2026 | G24: In Progress | H24: =IF(G24="Closed","",IFERROR(DATEVALUE(F24)-TODAY(),"")) -> -37 | I24: Due at MR-2026-Q2 | J24: AUDIT-003 | K24: CTL-011 | L24: Medium
A25: CA-003 | B25: Strengthen pre-issue guardrail for outlier features (pricing) | C25: INC-002 / PIR-002 | D25: Outlier feature interaction not handled | E25: Helen Carter | F25: 31/03/2026 | G25: Closed | H25: =IF(G25="Closed","",IFERROR(DATEVALUE(F25)-TODAY(),"")) | I25: Confirmed effective at MR-2025-Q4 | J25: INC-002 | K25: CTL-014 | L25: Medium
A26: CA-004 | B26: Sensitivity-label review cycle; Purview policy refresh | C26: INC-004 / PIR-004 | D26: SharePoint label inheritance gap | E26: Karen Holloway | F26: 30/09/2026 | G26: In Progress | H26: =IF(G26="Closed","",IFERROR(DATEVALUE(F26)-TODAY(),"")) -> 55 | I26: Due at MR-2026-Q2 | J26: INC-004 | K26: CTL-006 | L26: Medium
A27: CA-005 | B27: Vendor SLA exceptions; resilience plan updated for tabletop | C27: INC-005 / PIR-005 | D27: Vendor outage exposed DR gap | E27: James Whitfield | F27: 30/09/2026 | G27: In Progress | H27: =IF(G27="Closed","",IFERROR(DATEVALUE(F27)-TODAY(),"")) -> 55 | I27: Due at MR-2026-Q3 | J27: INC-005 | K27: CTL-005 | L27: Low
A28: CA-006 | B28: Confirm template update SLAs with ABBYY vendor | C28: INC-006 / PIR-006 | D28: New template not in training corpus | E28: Mohammed Iqbal | F28: 30/06/2026 | G28: Closed | H28: =IF(G28="Closed","",IFERROR(DATEVALUE(F28)-TODAY(),"")) | I28: Confirmed effective at MR-2026-Q1 | J28: INC-006 | K28: CTL-004 | L28: Low
A29: CA-007 | B29: PAM bundles re-baselined; quarterly review added | C29: INC-007 / PIR-007 | D29: Misconfigured PAM bundle | E29: Karen Holloway | F29: 31/03/2026 | G29: Closed | H29: =IF(G29="Closed","",IFERROR(DATEVALUE(F29)-TODAY(),"")) | I29: Confirmed effective at MR-2026-Q1 | J29: AUDIT-004, INC-007 | K29: CTL-013 | L29: Medium
A30: CA-008 | B30: Hallucination filter re-tune; vendor change-window QA alignment | C30: INC-008 / PIR-008 | D30: Filter regression after vendor model update | E30: Olivia Bennett | F30: 30/06/2026 | G30: Closed | H30: =IF(G30="Closed","",IFERROR(DATEVALUE(F30)-TODAY(),"")) | I30: Due at MR-2026-Q2 | J30: INC-008 | K30: CTL-010 | L30: High
A31: CA-009 | B31: Strengthen 9.3 management review input checklist | C31: AUDIT-001 (Major NC) | D31: MR input checklist incomplete vs Clause 9.3 requirements | E31: Andrew Pollard | F31: 30/06/2026 | G31: In Progress | H31: =IF(G31="Closed","",IFERROR(DATEVALUE(F31)-TODAY(),"")) -> -37 | I31: Due at MR-2026-Q2 | J31: AUDIT-001 | K31: Clause 9.3 | L31: High
A32: CA-010 | B32: Customer-facing AI impact assessments refresh | C32: AUDIT-002 (Major NC) | D32: Impact assessments not refreshed after vendor sub-processor changes | E32: Rebecca Lloyd | F32: 30/09/2026 | G32: In Progress | H32: =IF(G32="Closed","",IFERROR(DATEVALUE(F32)-TODAY(),"")) -> 55 | I32: Due at MR-2026-Q3 | J32: AUDIT-002 | K32: CTL-003, A.6.2.5 | L32: High
A33: CA-011 | B33: Tier-1 vendor exit plans (VEN-001, VEN-006) | C33: AUDIT-003 (Major NC) | D33: Exit plans incomplete for material vendors | E33: Sarah Mitchell | F33: 30/09/2026 | G33: In Progress | H33: =IF(G33="Closed","",IFERROR(DATEVALUE(F33)-TODAY(),"")) -> 55 | I33: Due at MR-2026-Q3 | J33: AUDIT-003 | K33: CTL-011, A.7.5 | L33: High
A34: CA-012 | B34: Accelerate Tier-1 vendor DD currency to 100% | C34: MR-2026-Q1 | D34: One Tier-1 vendor in renewal; DD expired | E34: Sarah Mitchell | F34: 30/06/2026 | G34: In Progress | H34: =IF(G34="Closed","",IFERROR(DATEVALUE(F34)-TODAY(),"")) -> -37 | I34: Due at MR-2026-Q2 | J34: MR-2026-Q1 | K34: CTL-011 | L34: Medium
... A36: CA-014 | B36: Lift training completion to 95% (AI awareness module) | C36: AUDIT-001 / MR-2026-Q1 | D36: Training at 86% vs 95% target; Clauses 7.2-7.3 gap | E36: Daniel O'Reilly | F36: 30/09/2026 | G36: In Progress | H36: =IF(G36="Closed","",IFERROR(DATEVALUE(F36)-TODAY(),"")) -> 55 | I36: Due at MR-2026-Q3 | J36: AUDIT-001 | K36: CTL-016, A.7.6 | L36: High
A38: Section 4: Post-Incident Review (PIR) Effectiveness Tracker
A39: PIR ID | B39: Incident | C39: Category | D39: Severity | E39: Corrective Action Taken | F39: Effectiveness Criteria | G39: Review Date | H39: Effectiveness Status | I39: Residual Gap | J39: Reviewer | K39: Linked CA | L39: Next Review
A40: PIR-001 | B40: INC-001 - Claims FNOL drift | C40: Model Drift | D40: Sev 2 | E40: Retraining with refreshed data; revised drift threshold; cadence increased | F40: No recurrence of drift on same model within 90 days; seasonal features validated | G40: 15/04/2026 | H40: Effective | I40: None | J40: Mohammed Iqbal | K40: CA-001 | L40: N/A
A41: PIR-002 | B41: INC-002 - UW pricing outlier | C41: Output Quality | D41: Sev 3 | E41: Added guardrail rule; updated pricing committee escalation | F41: No recurrence of uncontrolled outlier quote within 90 days | G41: 15/04/2026 | H41: Effective | I41: None | J41: Helen Carter | K41: CA-003 | L41: N/A
A42: PIR-003 | B42: INC-003 - Voice agent inaccurate suggestion | C42: Output Quality | D42: Sev 2 | E42: Index refresh automation; content owner cadence updated; sample QA increase | F42: No recurrence of stale-content surfacing; index freshness SLA met | G42: 15/04/2026 | H42: Effective | I42: None | J42: Olivia Bennett | L42: N/A
A43: PIR-004 | B43: INC-004 - M365 Copilot label leak | C43: Data Leakage | D43: Sev 3 | E43: Label review cycle introduced; Purview policy refresh | F43: No recurrence of label inheritance gap; quarterly label audit clean | G43: 15/07/2026 | H43: Pending | I43: Label inheritance on legacy sites | J43: Karen Holloway | K43: CA-004 | L43: MR-2026-Q2
A44: PIR-005 | B44: INC-005 - Tractable vendor outage | C44: Vendor Outage | D44: Sev 2 | E44: Vendor SLA exceptions; resilience plan updated; tabletop scheduled | F44: Tabletop exercise completed; fallback invoked within RTO | G44: 15/07/2026 | H44: Pending | I44: Tabletop not yet completed | J44: James Whitfield | K44: CA-005 | L44: MR-2026-Q2
A45: PIR-006 | B45: INC-006 - ABBYY extraction error | C45: Output Quality | D45: Sev 3 | E45: Vendor template update; QA sample increase | F45: Template SLA met; no recurrence on same format | G45: 15/04/2026 | H45: Effective | I45: None | J45: Mohammed Iqbal | K45: CA-006 | L45: N/A
...

Sheet Dashboard
A1: AI Security Manager Executive Dashboard V2 - Mid-Sized UK Insurer
A2: Formula-driven control tower for AI governance, risk, security, services, incidents, audit readiness, evidence, vendor assurance, roadmap and budget. Owner AI Security Manager. As at 02/05/2026.
A3: Open TOM Index for navigation | B3: Open ID Glossary
A5: 1. Headline Posture
A6: Active AI Use Cases | D6: Tier 1 Critical Use Cases | G6: ISO 42001 Audit Readiness | J6: Maturity Score Pct of Target
A7: =COUNTIF('AI Use Case Register'!R5:R26,"Approved") -> 20 | D7: =COUNTIF('AI Use Case Register'!Q5:Q26,"Tier 1") -> 11 | G7: =AVERAGE('[1]ISO 42001 Audit Readiness Matri'!K5:K42)/3 -> #REF! | J7: =SUM('Maturity Assessment'!D5:D13)/SUM('Maturity Assessment'!F5:F13) -> 0.76315789
A8: Approved use cases in production | D8: Tier 1 critical AI use cases | G8: Average readiness vs max 3 across 38 clauses + Annex A | J8: Composite of 9 maturity domains vs target
A9: High or Critical Residual Risks | D9: KRI Breaches Red | G9: Open Incidents | J9: Quantified Residual Exposure
A10: =COUNTIF('Risk Quantification'!K5:K17,">=15") -> 0 | D10: =COUNTIF('KRI Tracking'!J5:J13,"Red") -> 0 | G10: =COUNTIF('Incident Analysis'!M5:M12,"Open")+COUNTIF('Incident Analysis'!M5:M12,"Under Review") -> 0 | J10: =SUM('Risk Quantification'!L5:L17) -> 53.7
A11: Residual score 15 or higher (max 25) | D11: KRIs above red threshold | G11: Open or under review (rolling 90d) | J11: Total residual exposure across 13 risks
A13: 2. ISO/IEC 42001 Audit Readiness
A14: Clauses Audit Ready | D14: Clauses Major NC Risk | G14: Evidence Items Stale | J14: Evidence Items Due Soon
A15: =COUNTIF('[1]ISO 42001 Audit Readiness Matri'!K5:K42,3) -> #VALUE! | D15: =COUNTIF('[1]ISO 42001 Audit Readiness Matri'!L5:L42,"Major*") -> #VALUE! | G15: =COUNTIF('[2]Evidence Register'!O5:O34,"Stale") -> #VALUE! | J15: =COUNTIF('[2]Evidence Register'!O5:O34,"Due Soon") -> #VALUE!
A16: Score of 3 (Audit Ready) out of 38 items | D16: Items where absence is potential major nonconformity | G16: Evidence past next-review date | J16: Evidence due in next 30 days
A17: Controls Implemented | D17: Controls Partial | G17: Controls with Open Gap | J17: Controls Lacking Evidence
A18: =COUNTIF('Compliance Mapping'!K5:K20,"Implemented") -> 12 | D18: =COUNTIF('Compliance Mapping'!K5:K20,"Partially Implemented") -> 4 | G18: =SUMPRODUCT(('Compliance Mapping'!P5:P20<>"No material gaps")*(LEN('Compliance Mapping'!P5:P20)>0)) -> 6 | J18: =COUNTBLANK('Compliance Mapping'!L5:L20) -> 0
A19: Out of 16 controls in scope | D19: Controls with open implementation gaps | G19: Controls with documented residual gap | J19: Controls with no linked evidence ID
A21: 3. Service Delivery, Incidents and Vendor Assurance
A22: Open Service Requests | D22: SLA Met Rate | G22: Tier 1 Vendor DD Currency | J22: Vendor Reviews Overdue
A23: =COUNTIF('Service Request Log'!H5:H28,"Open")+COUNTIF('Service Request Log'!H5:H28,"In Progress") -> 6 | D23: =COUNTIF('Service Request Log'!L5:L28,"Yes")/(COUNTIF('Service Request Log'!L5:L28,"Yes")+COUNTIF('Service Request Log'!L5:L28,"No")) -> 0.88888889 | G23: =COUNTIF('Third-Party Risk Services'!G5:G20,"Complete")/COUNTA('Third-Party Risk Services'!G5:G20) -> 0.9375 | J23: =SUMPRODUCT(('Third-Party Risk Services'!J5:J20<TODAY())*1) -> 0
A24: Open or in flight requests | D24: Pct of closed requests within SLA | G24: Pct of vendors with current due diligence | J24: Vendors with contract renewal date in past
A25: Sev 1 or 2 Incidents (90d) | D25: Avg Days to Close Request | G25: KRI Amber | J25: Evidence Currency Pct
A26: =COUNTIF('Incident Analysis'!D5:D12,"Sev 1")+COUNTIF('Incident Analysis'!D5:D12,"Sev 2") -> 4 | D26: =AVERAGEIF('Service Request Log'!H5:H28,"Closed",'Service Request Log'!K5:K28) -> 13.5 | G26: =COUNTIF('KRI Tracking'!J5:J13,"Amber") -> 2 | J26: =COUNTIF('[2]Evidence Register'!O5:O34,"Current")/COUNTA('[2]Evidence Register'!O5:O34) -> #VALUE!
A27: Sev 1 and Sev 2 in rolling 90 days | D27: Mean ageing of closed requests (days) | G27: KRIs in amber zone | J27: Evidence items current vs total
A29: 4. Roadmap, Budget and People
A30: Roadmap Avg Pct Complete | D30: Total FY 26 27 Budget | G30: Budget Variance | J30: FTE Gap Vacancies
A31: =AVERAGE('Implementation Roadmap'!I5:I16) -> 0.375 | D31: ='Financial Analysis'!E34 -> 6159.3 | G31: ='Financial Analysis'!H34 -> -58 | J31: =SUM('Resource Planning'!D5:D16)-SUM('Resource Planning'!C5:C16) -> 5
A32: Weighted across 12 roadmap items | D32: Run plus Change plus Contingency | G32: Negative equals favourable underspend | J32: Open vacancies vs target
A33: Roadmap Items On Track | D33: Roadmap Items At Risk | G33: Open Corrective Actions | J33: Overdue Corrective Actions
A34: =COUNTIF('Implementation Roadmap'!H5:H16,"On Track")+COUNTIF('Implementation Roadmap'!H5:H16,"In Progress") -> 10 | D34: =COUNTIF('Implementation Roadmap'!H5:H16,"Delayed")+COUNTIF('Implementation Roadmap'!H5:H16,"Not Started") -> 2 | G34: =COUNTIF('[3]Management Review and Internal '!G24:G37,"Open")+COUNTIF('[3]Management Review and Internal '!G24:G37,"In Progress") -> #VALUE! | J34: =SUMPRODUCT(('[3]Management Review and Internal '!G24:G37<>"Closed")*('[3]Management Review and Internal '!F24:F37<TODAY())*1) -> #REF!
A35: On Track or In Progress workstreams | D35: Delayed or Not Started workstreams | G35: Open or In Progress corrective actions | J35: Open actions past target date
A37: 5. Top 5 Residual Risks (by Quantified Exposure)
A38: Risk ID | C38: Risk Title | F38: Residual Score | G38: Exposure | H38: Treatment | J38: Owner
A39: RSK-011 | C39: Regulatory breach (Consumer Duty / fairness / FCA) | F39: ='Risk Quantification'!K15 -> 10 | G39: ='Risk Quantification'!L15 -> 7.5 | H39: ='Risk Quantification'!M15 -> Mitigate | J39: Rebecca Lloyd
A40: RSK-001 | C40: Model performance drift causing pricing/UW losses | F40: ='Risk Quantification'!K5 -> 8 | G40: ='Risk Quantification'!L5 -> 6.5 | H40: ='Risk Quantification'!M5 -> Mitigate | J40: Mohammed Iqbal
A41: RSK-010 | C41: Cloud misconfiguration exposing AI workloads | F41: ='Risk Quantification'!K14 -> 10 | G41: ='Risk Quantification'!L14 -> 6 | H41: ='Risk Quantification'!M14 -> Mitigate | J41: Karen Holloway
A42: RSK-004 | C42: Pricing or fairness bias against protected groups | F42: ='Risk Quantification'!K8 -> 8 | G42: ='Risk Quantification'!L8 -> 5.5 | H42: ='Risk Quantification'!M8 -> Mitigate | J42: Helen Carter
A43: RSK-005 | C43: LLM hallucination delivered to customer | F43: ='Risk Quantification'!K9 -> 8 | G43: ='Risk Quantification'!L9 -> 4.8 | H43: ='Risk Quantification'!M9 -> Mitigate | J43: Olivia Bennett
A45: 6. Top 10 Remediation Actions (overdue first, then due soon)
A46: Action ID | C46: Action | G46: Owner | H46: Target Date | J46: Days to Target | K46: Status
...

Sheet Executive Report
A1: Executive Report V2 - AI Security and Governance Posture
A2: Quarterly leadership view of AI security, governance, risk, audit readiness, evidence and roadmap. Owner AI Security Manager. Reporting Period Q1 2026. Audience Board, ExCo, Risk Committee, Audit Committee.
A3: Back to Dashboard
B5: 1. Executive Summary
B6: The AI Security function is on a credible glide-path toward ISO/IEC 42001 internal readiness review by Q4 2026 and certification readiness assessment in Q1 2027 (RDM-007). 22 AI use cases are in production, of which 11 are Tier 1 and customer-impacting. The composite maturity score is 3.22 of 5.00 against a target of 4.22 (76 percent of target). Across 38 ISO/IEC 42001 clauses and Annex A controls, 3 items are Audit Ready (score 3) and 24 are Ready with minor gaps (score 2); average readiness is 1.95 (65 percent of max). Twelve items carry potential major nonconformity risk if absent and are the focus of remediation. There are no Red KRI breaches; two KRIs are Amber under remediation. Quantified residual exposure is 53.7m, dominated by RSK-011 Regulatory breach (7.5m) and RSK-010 Cloud misconfiguration (6.0m).
B8: 2. ISO/IEC 42001 Audit Readiness Posture
B9: ISO/IEC 42001 readiness is the function's primary focus. The AIMS scope, AI policy, and governance framework are documented and approved (EVD-023, EVD-024, EVD-027). Risk management (Clause 6.1), operational controls (Clause 8.1) and performance evaluation (Clause 9.1) are operating with strong evidence. Three areas carry the largest residual gap and are the most likely sources of nonconformity at audit if not closed - (a) AI system impact assessments under Clause 6.1.4 and Annex A.6.2.5 where customer-facing assessments require refresh after vendor sub-processor changes (CA-010); (b) third-party AI substitutability under Clause 8.1 and Annex A.7.5 where Tier-1 vendor exit plans are incomplete for VEN-001 and VEN-006 (CA-011); and (c) competence and awareness under Clauses 7.2-7.3 and Annex A.7.6 where training completion is 86 percent against a 95 percent target (CA-014). The function does not claim certification will be achieved - certification ultimately depends on assessor judgement and the actual implementation observed. Internal readiness review (AUDIT-006) is scheduled for September 2026.
B11: 3. Strategic Posture
B12: The AI estate continues to expand within Risk Appetite. Internal models (underwriting, claims triage, fraud, pricing) remain robust with strong assurance and monitoring coverage at 92 percent for Tier 1 models. Customer-facing AI (voice agent assist, vulnerable customer detection, smart search) has matured with output guardrails, sample QA, complaint linkage, and refreshed hallucination filter post INC-008. Generative AI productivity tooling is embedded with Microsoft Purview controls; legacy SharePoint label inheritance is the residual gap (CA-004). The Splunk to Sentinel migration (RDM-010) is 60 percent complete and on track to retire dual-running cost in Q4 2026.
B14: 4. Top 5 Material Risks (by Quantified Residual Exposure)
B15: Risk ID | C15: Risk | D15: Residual Score | E15: Exposure | F15: Treatment | G15: Owner
B16: RSK-011 | C16: Regulatory breach (Consumer Duty, fairness, FCA) | D16: ='Risk Quantification'!K15 -> 10 | E16: ='Risk Quantification'!L15 -> 7.5 | F16: Mitigate | G16: Rebecca Lloyd
B17: RSK-001 | C17: Model performance drift causing pricing/UW losses | D17: ='Risk Quantification'!K5 -> 8 | E17: ='Risk Quantification'!L5 -> 6.5 | F17: Mitigate | G17: Mohammed Iqbal
B18: RSK-010 | C18: Cloud misconfiguration exposing AI workloads | D18: ='Risk Quantification'!K14 -> 10 | E18: ='Risk Quantification'!L14 -> 6 | F18: Mitigate | G18: Karen Holloway
B19: RSK-004 | C19: Pricing or fairness bias against protected groups | D19: ='Risk Quantification'!K8 -> 8 | E19: ='Risk Quantification'!L8 -> 5.5 | F19: Mitigate | G19: Helen Carter
B20: RSK-005 | C20: LLM hallucination delivered to customer | D20: ='Risk Quantification'!K9 -> 8 | E20: ='Risk Quantification'!L9 -> 4.8 | F20: Mitigate | G20: Olivia Bennett
B22: 5. Likely Audit Test Focus and Interview Owners (Top 10 by Audit Sensitivity)
B23: Clause / Annex A | C23: Test Focus | D23: Interview Owner | E23: Readiness Score | F23: Status | G23: Linked Evidence
B24: Clause 4.3 - Scope of AIMS | C24: Auditor will request AIMS scope statement and trace it to actual AI estate | D24: AI Security Manager | E24: 3 | F24: Audit Ready | G24: EVD-023
B25: Clause 5.2 - AI Policy | C25: Auditor will check policy approval, version control, and that staff can articulate it | D25: AI Security Manager / CDO | E25: 3 | F25: Audit Ready | G25: EVD-024
B26: Clause 6.1.2 - AI risk assessment | C26: Auditor will sample risk records and re-perform on selected use case | D26: CRO / AI Security Manager | E26: 2 | F26: Ready (minor gaps) | G26: EVD-008
B27: Clause 6.1.4 / A.6.2.5 - AI system impact assessment | C27: Auditor will sample 2-3 material use cases and request full impact assessment | D27: AI Security Manager / DPO | E27: 2 | F27: Ready (minor gaps) | G27: EVD-004,EVD-008
B28: Clause 7.3 / A.7.6 - Awareness and training | C28: Auditor will interview random colleagues to test awareness | D28: AI Security Manager / Comms | E28: 1 | F28: Partial - Major NC risk | G28: EVD-029
B29: Clause 8.1 / A.7.5 - Vendor exit | C29: Auditor will check exit-plan completeness for material vendors | D29: Sarah Mitchell | E29: 1 | F29: Partial - Major NC risk | G29: EVD-030
